Workbook

Sheet Quiebres
A1: QUIEBRE de art importados
H3: 8 | N3: Ultimos tres meses de ventas
A4: Cod Art | B4: Marca | C4: Proveedor | D4: Descripcion | E4: FOB | F4: Total FOB | G4: Genera Pedido | H4: Maximo Determinado | I4: Total Stock | J4: Meses | K4: Stock Actual | L4: Pedido en Curso | M4: Est Madre | N4: May 26 Uni | O4: Abr 26 Uni | P4: Mzo 26 Uni | Q4: Observaciones
A5: 951E | B5: LK | C5: Becky 1 | D5: Espatula lisa Silic Mgo Bambú | E5: 0.49 | G5: =IF((+H5-I5)<0,"",+H5-I5) -> 1116 | H5: =+$H$3*M5 -> 3360 | I5: =+K5+L5 -> 2244 | J5: =+I5/M5 -> 5.3428571 | K5: 228 | L5: 2016 | M5: 420 | N5: 432 | O5: 216 | P5: 72
A7: 438E | B7: LK | C7: Fujian | D7: Colador 20cm ac. inox. | E7: 0.78 | G7: =IF((+H7-I7)<0,"",+H7-I7) -> 2400 | H7: =+$H$3*M7 -> 2688 | I7: =+K7+L7 -> 288 | J7: =+I7/M7 -> 0.85714286 | K7: 288 | L7: 0 | M7: 336 | N7: 96 | O7: 984 | P7: 0
A8: 440E | B8: LK | C8: Fujian | D8: Colador Extensible Ac. Inox. | E8: 4.26 | G8: =IF((+H8-I8)<0,"",+H8-I8) -> 840 | H8: =+$H$3*M8 -> 960 | I8: =+K8+L8 -> 120 | J8: =+I8/M8 -> 1 | K8: 120 | L8: 0 | M8: 120 | N8: 56 | O8: 52 | P8: 80
A9: 035E | B9: LK | C9: Fujian | D9: Cernidor Harina Ac. Inox. | E9: 0.85 | G9: =IF((+H9-I9)<0,"",+H9-I9) -> 1344 | H9: =+$H$3*M9 -> 1920 | I9: =+K9+L9 -> 576 | J9: =+I9/M9 -> 2.4 | K9: 576 | L9: 0 | M9: 240 | N9: 132 | O9: 324 | P9: 384
A11: 529E | B11: LK | C11: Hugo Wong | D11: Sac. Doble Impulso Acero | E11: 0.465 | G11: =IF((+H11-I11)<0,"",+H11-I11) -> 11596 | H11: =+$H$3*M11 -> 35200 | I11: =+K11+L11 -> 23604 | J11: =+I11/M11 -> 5.3645455 | K11: 2868 | L11: 20736 | M11: 4400 | N11: 3492 | O11: 2208 | P11: 7140
A12: 522E | B12: LK | C12: Hugo Wong | D12: Sac. Doble Aleta Premium | E12: 1.4 | G12: =IF((+H12-I12)<0,"",+H12-I12) -> 2880 | H12: =+$H$3*M12 -> 7200 | I12: =+K12+L12 -> 4320 | J12: =+I12/M12 -> 4.8 | K12: 2280 | L12: 2040 | M12: 900 | N12: 132 | O12: 756 | P12: 1536
A13: 102E | B13: Loke | C13: Hugo Wong | D13: Abr Mariposa Loke | E13: 0.38 | G13: =IF((+H13-I13)<0,"",+H13-I13) -> 16580 | H13: =+$H$3*M13 -> 32000 | I13: =+K13+L13 -> 15420 | J13: =+I13/M13 -> 3.855 | K13: 6060 | L13: 9360 | M13: 4000 | N13: 2280 | O13: 4260 | P13: 2580 | Q13: (se reenvaso para 702EN - esp. Walmart)
A14: 323E | B14: LK | C14: Hugo Wong | D14: Rallador 4 Lados Mini | E14: 0.225 | G14: =IF((+H14-I14)<0,"",+H14-I14) -> 4400 | H14: =+$H$3*M14 -> 6400 | I14: =+K14+L14 -> 2000 | J14: =+I14/M14 -> 2.5 | K14: 0 | L14: 2000 | M14: 800 | N14: 108 | O14: 180 | P14: 504
A16: 865E | B16: CH | C16: Kangli | D16: Rallador plano a/I 3 usos | G16: =IF((+H16-I16)<0,"",+H16-I16) -> 576 | H16: =+$H$3*M16 -> 960 | I16: =+K16+L16 -> 384 | J16: =+I16/M16 -> 3.2 | K16: 384 | L16: 0 | M16: 120 | N16: 12 | O16: 0 | P16: 0 | Q16: lo lleva Dorinka (se tomo 865E+ED)
A17: 360E | B17: LK | C17: Kangli | D17: Rallador 4 Lados A/L Mgo Plast | G17: =IF((+H17-I17)<0,"",+H17-I17) -> 3348 | H17: =+$H$3*M17 -> 3744 | I17: =+K17+L17 -> 396 | J17: =+I17/M17 -> 0.84615385 | K17: 396 | L17: 0 | M17: 468 | N17: 336 | O17: 468 | P17: 432 | Q17: me parece que dijiste que no te gustaba
A18: 328E | B18: LK | C18: Kangli | D18: Rallador Plano 3 Usos Ac Inox | G18: =IF((+H18-I18)<0,"",+H18-I18) -> 1344 | H18: =+$H$3*M18 -> 3360 | I18: =+K18+L18 -> 2016 | J18: =+I18/M18 -> 4.8 | K18: 0 | L18: 2016 | M18: 420 | N18: 336 | O18: 420 | P18: 732
A20: 733E | B20: CH | C20: Ownland | D20: Sacacorcho doble impulso pint. | G20: =IF((+H20-I20)<0,"",+H20-I20) -> 6336 | H20: =+$H$3*M20 -> 6336 | I20: =+K20+L20 -> 0 | J20: =+I20/M20 -> 0 | K20: 0 | L20: 0 | M20: 792 | N20: 0 | O20: 0 | P20: 0 | Q20: discontinuo
A21: 692E | B21: CH | C21: Ownland | D21: Pelador "v" horizontal | G21: =IF((+H21-I21)<0,"",+H21-I21) -> 1920 | H21: =+$H$3*M21 -> 1920 | I21: =+K21+L21 -> 0 | J21: =+I21/M21 -> 0 | K21: 0 | L21: 0 | M21: 240 | N21: 0 | O21: 0 | P21: 0 | Q21: discontinuo
A22: 727E | B22: CH | C22: Ownland | D22: Sacacorcho Doble Imp. Ac x12 | G22: =IF((+H22-I22)<0,"",+H22-I22) -> 1920 | H22: =+$H$3*M22 -> 1920 | I22: =+K22+L22 -> 0 | J22: =+I22/M22 -> 0 | K22: 0 | L22: 0 | M22: 240 | N22: 372 | O22: 1452 | P22: 468 | Q22: se compraba
A23: 877E | B23: CH | C23: Ownland | D23: Corta Pizza Mgo Ergonomico  6 | G23: =IF((+H23-I23)<0,"",+H23-I23) -> 1632 | H23: =+$H$3*M23 -> 1632 | I23: =+K23+L23 -> 0 | J23: =+I23/M23 -> 0 | K23: 0 | L23: 0 | M23: 204 | N23: 252 | O23: 240 | P23: 0 | Q23: discontinuo (se le vende a Dorinka)
A24: 729E | B24: CH | C24: Ownland | D24: Sac. doble aleta fundicion | G24: =IF((+H24-I24)<0,"",+H24-I24) -> 2112 | H24: =+$H$3*M24 -> 2208 | I24: =+K24+L24 -> 96 | J24: =+I24/M24 -> 0.34782609 | K24: 96 | L24: 0 | M24: 276 | N24: 96 | O24: 60 | P24: 144 | Q24: se compraba
A25: 580E | B25: LK | C25: Ownland | D25: Batidor Mini | G25: =IF((+H25-I25)<0,"",+H25-I25) -> 4908 | H25: =+$H$3*M25 -> 5472 | I25: =+K25+L25 -> 564 | J25: =+I25/M25 -> 0.8245614 | K25: 564 | L25: 0 | M25: 684 | N25: 696 | O25: 960 | P25: 996 | Q25: + barato nacional
A26: 525E | B26: LK | C26: Ownland | D26: Sacacorcho Cabo De Madera | G26: =IF((+H26-I26)<0,"",+H26-I26) -> 9432 | H26: =+$H$3*M26 -> 14400 | I26: =+K26+L26 -> 4968 | J26: =+I26/M26 -> 2.76 | K26: 1800 | L26: 3168 | M26: 1800 | N26: 576 | O26: 1344 | P26: 2472 | Q26: mayor consumo (megashop)
A27: 585E | B27: LK | C27: Ownland | D27: Sac. Doble Aleta Fundicion | G27: =IF((+H27-I27)<0,"",+H27-I27) -> 5412 | H27: =+$H$3*M27 -> 9600 | I27: =+K27+L27 -> 4188 | J27: =+I27/M27 -> 3.49 | K27: 4188 | L27: 0 | M27: 1200 | N27: 516 | O27: 1140 | P27: 1452 | Q27: mayor consumo (megashop/Jumbo)
A28: 809E | B28: LK | C28: Ownland | D28: Corta pizza familiar | G28: =IF((+H28-I28)<0,"",+H28-I28) -> 936 | H28: =+$H$3*M28 -> 2304 | I28: =+K28+L28 -> 1368 | J28: =+I28/M28 -> 4.75 | K28: 1368 | L28: 0 | M28: 288 | N28: 288 | O28: 216 | P28: 324
A29: 809E | B29: LK | C29: Ownland | D29: CORTA QUESO x 12 | G29: =IF((+H29-I29)<0,"",+H29-I29) -> 5040 | H29: =+$H$3*M29 -> 13440 | I29: =+K29+L29 -> 8400 | J29: =+I29/M29 -> 5 | K29: 4368 | L29: 4032 | M29: 1680 | N29: 1248 | O29: 948 | P29: 744
A30: 819E | B30: LK | C30: Ownland | D30: Sacacorcho "Fish" Grande | G30: =IF((+H30-I30)<0,"",+H30-I30) -> 1776 | H30: =+$H$3*M30 -> 4800 | I30: =+K30+L30 -> 3024 | J30: =+I30/M30 -> 5.04 | K30: 3024 | L30: 0 | M30: 600 | N30: 396 | O30: 516 | P30: 1248
A31: 702E | B31: CH | C31: Ownland | D31: Abrelata mariposa. | G31: =IF((+H31-I31)<0,"",+H31-I31) -> 2976 | H31: =+$H$3*M31 -> 9600 | I31: =+K31+L31 -> 6624 | J31: =+I31/M31 -> 5.52 | K31: 0 | L31: 6624 | M31: 1200 | N31: 0 | O31: 1620 | P31: 1068
A32: 817E | B32: LK | C32: Ownland | D32: Rallador C/Mgo Ergonomico | G32: =IF((+H32-I32)<0,"",+H32-I32) -> 876 | H32: =+$H$3*M32 -> 3360 | I32: =+K32+L32 -> 2484 | J32: =+I32/M32 -> 5.9142857 | K32: 2484 | L32: 0 | M32: 420 | N32: 96 | O32: 252 | P32: 420
A34: 590ES | B34: LK | C34: Zhixin | D34: Pincel Silicona 11 Gms Suelto | G34: =IF((+H34-I34)<0,"",+H34-I34) -> 732 | H34: =+$H$3*M34 -> 960 | I34: =+K34+L34 -> 228 | J34: =+I34/M34 -> 1.9 | K34: 228 | L34: 0 | M34: 120 | N34: 0 | O34: 0 | P34: 84
A35: 890E | B35: CH | C35: Zhixin | D35: Pincel Silicona 11 Gms | G35: =IF((+H35-I35)<0,"",+H35-I35) -> 1524 | H35: =+$H$3*M35 -> 2016 | I35: =+K35+L35 -> 492 | J35: =+I35/M35 -> 1.952381 | K35: 492 | L35: 0 | M35: 252 | N35: 0 | O35: 72 | P35: 36
A36: 590+890 | G36: =+SUM(G34:G35) -> 2256 | H36: =+SUM(H34:H35) -> 2976 | I36: =+SUM(I34:I35) -> 720 | J36: =+SUM(J34:J35) -> 3.852381 | K36: =+SUM(K34:K35) -> 720 | L36: =+SUM(L34:L35) -> 0 | M36: =+SUM(M34:M35) -> 372 | N36: =+SUM(N34:N35) -> 0 | ... P36: =+SUM(P34:P35) -> 120 | Q36: todo junto
A37: 582E | B37: LK | C37: Zhixin | D37: Salero | G37: =IF((+H37-I37)<0,"",+H37-I37) -> 16920 | H37: =+$H$3*M37 -> 27456 | I37: =+K37+L37 -> 10536 | J37: =+I37/M37 -> 3.0699301 | K37: 10536 | L37: 0 | M37: 3432 | N37: 3096 | O37: 3384 | P37: 1728 | Q37: mayor consumo (Coto)
A38: 566E | B38: LK | C38: Zhixin | D38: Aceitera 100 ml | G38: =IF((+H38-I38)<0,"",+H38-I38) -> 2196 | H38: =+$H$3*M38 -> 3840 | I38: =+K38+L38 -> 1644 | J38: =+I38/M38 -> 3.425 | K38: 1644 | L38: 0 | M38: 480 | N38: 360 | O38: 630 | P38: 708
A39: 583E | B39: LK | C39: Zhixin | D39: Especiero Doble Boqui | G39: =IF((+H39-I39)<0,"",+H39-I39) -> 7243 | H39: =+$H$3*M39 -> 15448 | I39: =+K39+L39 -> 8205 | J39: =+I39/M39 -> 4.2490937 | K39: 8205 | L39: 0 | M39: 1931 | N39: 1875 | O39: 2535 | P39: 2445

Sheet Todos
A1: QUIEBRE de art importados
B2: No esta en Cotizador/ Art Nuevo o Discontinuo
B3: Partes | E3: Becky | F3: =+SUM(F5:F66) -> 0 | I3: 8 | O3: Ultimos tres meses de ventas
A4: Cod Art | B4: Marca | C4: Proveedor | D4: Descripcion | E4: FOB Uni | F4: Total FOB | G4: Genera Pedido | H4: Pedido Manual | I4: Maximo Determinado | J4: Meses | K4: Stock Actual | L4: Pedido en Curso | M4: Total Stock | N4: Est Madre | O4: May 26 Uni | P4: Abr 26 Uni | Q4: Mzo 26 Uni | R4: Observaciones | S4: Cotizador
A5: 951E | B5: LK | C5: Becky 1 | D5: Espatula lisa Silic Mgo Bambú | E5: 0.49 | F5: =+E5*IF(ISNUMBER(H5),H5,G5) -> 0 | G5: =IF((+I5-M5)<0,0,+I5-M5) -> 0 | H5: 0 | I5: =+$I$3*N5 -> 3360 | J5: =IFERROR(+M5/N5,"") -> 8.0571429 | K5: =+IF(B5<>"CH",IFERROR(VLOOKUP(A5,'Stock Loeke'!A:G,7,),),)+IF(B5="CH",IFERROR(VLOOKUP(A5,'Stock Chef'!A:J,10,),0),0) -> 216 | L5: =2016+1152 -> 3168 | M5: =+K5+L5 -> 3384 | N5: 420 | O5: 432 | P5: 216 | Q5: 72 | R5: Agregar al pedido en curso | S5: 951E
A6: 970E | B6: LK | C6: Becky 2 | D6: Cuchara Silicona Mgo. Plastico | E6: 0.44 | F6: =+E6*IF(ISNUMBER(H6),H6,G6) -> 0 | G6: =IF((+I6-M6)<0,0,+I6-M6) -> 528 | H6: 0 | I6: =+$I$3*N6 -> 2112 | J6: =IFERROR(+M6/N6,"") -> 6 | K6: =+IF(B6<>"CH",IFERROR(VLOOKUP(A6,'Stock Loeke'!A:G,7,),),)+IF(B6="CH",IFERROR(VLOOKUP(A6,'Stock Chef'!A:J,10,),0),0) -> 576 | L6: 1008 | M6: =+K6+L6 -> 1584 | N6: 264 | O6: 864 | P6: 180 | Q6: 168 | R6: =IFERROR(+VLOOKUP(A6,Quiebres!A:Q,17,0),"") | S6: 970E
A7: 936E | B7: LK | C7: Becky 1 | D7: Espumadera Nylon Mgo Madera | E7: 0.53 | F7: =+E7*IF(ISNUMBER(H7),H7,G7) -> 0 | G7: =IF((+I7-M7)<0,0,+I7-M7) -> 576 | H7: 0 | I7: =+$I$3*N7 -> 2400 | J7: =IFERROR(+M7/N7,"") -> 6.08 | K7: =+IF(B7<>"CH",IFERROR(VLOOKUP(A7,'Stock Loeke'!A:G,7,),),)+IF(B7="CH",IFERROR(VLOOKUP(A7,'Stock Chef'!A:J,10,),0),0) -> 816 | L7: 1008 | M7: =+K7+L7 -> 1824 | N7: 300 | O7: 420 | P7: 180 | Q7: 336 | R7: =IFERROR(+VLOOKUP(A7,Quiebres!A:Q,17,0),"") | S7: 936E
A8: 952E | B8: LK | C8: Becky 1 | D8: Cuchara Silicona Mgo Bambú | E8: 0.49 | F8: =+E8*IF(ISNUMBER(H8),H8,G8) -> 0 | G8: =IF((+I8-M8)<0,0,+I8-M8) -> 740 | H8: 0 | I8: =+$I$3*N8 -> 3200 | J8: =IFERROR(+M8/N8,"") -> 6.15 | K8: =+IF(B8<>"CH",IFERROR(VLOOKUP(A8,'Stock Loeke'!A:G,7,),),)+IF(B8="CH",IFERROR(VLOOKUP(A8,'Stock Chef'!A:J,10,),0),0) -> 12 | L8: 2448 | M8: =+K8+L8 -> 2460 | N8: 400 | O8: 504 | P8: 228 | Q8: 144 | R8: =IFERROR(+VLOOKUP(A8,Quiebres!A:Q,17,0),"") | S8: 952E
A9: 992E | B9: LK | C9: Becky | D9: Batidor Pera Mgo Acacia | E9: 0.61 | F9: =+E9*IF(ISNUMBER(H9),H9,G9) -> 0 | G9: =IF((+I9-M9)<0,0,+I9-M9) -> 0 | H9: 0 | I9: =+$I$3*N9 -> 576 | J9: =IFERROR(+M9/N9,"") -> 8 | K9: =+IF(B9<>"CH",IFERROR(VLOOKUP(A9,'Stock Loeke'!A:G,7,),),)+IF(B9="CH",IFERROR(VLOOKUP(A9,'Stock Chef'!A:J,10,),0),0) -> 0 | L9: 576 | M9: =+K9+L9 -> 576 | N9: 72 | O9: 0 | P9: 72 | Q9: 36
A10: 999E | B10: LK | C10: Becky | D10: Pica Ajo Mgo Acacia | E10: 1.27 | F10: =+E10*IF(ISNUMBER(H10),H10,G10) -> 0 | G10: =IF((+I10-M10)<0,0,+I10-M10) -> 0 | H10: 0 | I10: =+$I$3*N10 -> 576 | J10: =IFERROR(+M10/N10,"") -> 8 | K10: =+IF(B10<>"CH",IFERROR(VLOOKUP(A10,'Stock Loeke'!A:G,7,),),)+IF(B10="CH",IFERROR(VLOOKUP(A10,'Stock Chef'!A:J,10,),0),0) -> 0 | L10: 576 | M10: =+K10+L10 -> 576 | N10: 72 | O10: 0 | P10: 72 | Q10: 48
A11: 993E | B11: LK | C11: Becky | D11: Pelador V Mgo Acacia | E11: 0.6 | F11: =+E11*IF(ISNUMBER(H11),H11,G11) -> 0 | G11: =IF((+I11-M11)<0,0,+I11-M11) -> 0 | H11: 0 | I11: =+$I$3*N11 -> 480 | J11: =IFERROR(+M11/N11,"") -> 9.6 | K11: =+IF(B11<>"CH",IFERROR(VLOOKUP(A11,'Stock Loeke'!A:G,7,),),)+IF(B11="CH",IFERROR(VLOOKUP(A11,'Stock Chef'!A:J,10,),0),0) -> 0 | L11: 576 | M11: =+K11+L11 -> 576 | N11: 60 | O11: 0 | P11: 60 | Q11: 24
A12: 994E | B12: LK | C12: Becky | D12: Pelador Mgo Acacia | E12: 0.52 | F12: =+E12*IF(ISNUMBER(H12),H12,G12) -> 0 | G12: =IF((+I12-M12)<0,0,+I12-M12) -> 0 | H12: 0 | I12: =+$I$3*N12 -> 480 | J12: =IFERROR(+M12/N12,"") -> 9.6 | K12: =+IF(B12<>"CH",IFERROR(VLOOKUP(A12,'Stock Loeke'!A:G,7,),),)+IF(B12="CH",IFERROR(VLOOKUP(A12,'Stock Chef'!A:J,10,),0),0) -> 0 | L12: 576 | M12: =+K12+L12 -> 576 | N12: 60 | O12: 0 | P12: 60 | Q12: 24
A13: 997E | B13: LK | C13: Becky | D13: Rallador 3 Usos Mgo Acacia | E13: 0.61 | F13: =+E13*IF(ISNUMBER(H13),H13,G13) -> 0 | G13: =IF((+I13-M13)<0,0,+I13-M13) -> 0 | H13: 0 | I13: =+$I$3*N13 -> 480 | J13: =IFERROR(+M13/N13,"") -> 9.6 | K13: =+IF(B13<>"CH",IFERROR(VLOOKUP(A13,'Stock Loeke'!A:G,7,),),)+IF(B13="CH",IFERROR(VLOOKUP(A13,'Stock Chef'!A:J,10,),0),0) -> 0 | L13: 576 | M13: =+K13+L13 -> 576 | N13: 60 | O13: 0 | P13: 60 | Q13: 24
A14: 998E | B14: LK | C14: Becky | D14: Abrelatas Doble Engranaje Mgo | E14: 1.36 | F14: =+E14*IF(ISNUMBER(H14),H14,G14) -> 0 | G14: =IF((+I14-M14)<0,0,+I14-M14) -> 0 | H14: 0 | I14: =+$I$3*N14 -> 480 | J14: =IFERROR(+M14/N14,"") -> 9.6 | K14: =+IF(B14<>"CH",IFERROR(VLOOKUP(A14,'Stock Loeke'!A:G,7,),),)+IF(B14="CH",IFERROR(VLOOKUP(A14,'Stock Chef'!A:J,10,),0),0) -> 0 | L14: 576 | M14: =+K14+L14 -> 576 | N14: 60 | O14: 0 | P14: 60 | Q14: 24
A15: 990E | B15: LK | C15: Becky | D15: Corta Ravioles Mgo Acacia | E15: 0.56 | F15: =+E15*IF(ISNUMBER(H15),H15,G15) -> 0 | G15: =IF((+I15-M15)<0,0,+I15-M15) -> 0 | H15: 0 | I15: =+$I$3*N15 -> 288 | J15: =IFERROR(+M15/N15,"") -> 16 | K15: =+IF(B15<>"CH",IFERROR(VLOOKUP(A15,'Stock Loeke'!A:G,7,),),)+IF(B15="CH",IFERROR(VLOOKUP(A15,'Stock Chef'!A:J,10,),0),0) -> 0 | L15: 576 | M15: =+K15+L15 -> 576 | N15: 36 | O15: 0 | P15: 36 | Q15: 24
A16: 996E | B16: LK | C16: Becky | D16: Corta Pizza 9cm Mgo Acacia | E16: 0.71 | F16: =+E16*IF(ISNUMBER(H16),H16,G16) -> 0 | G16: =IF((+I16-M16)<0,0,+I16-M16) -> 0 | H16: 0 | I16: =+$I$3*N16 -> 192 | J16: =IFERROR(+M16/N16,"") -> 24 | K16: =+IF(B16<>"CH",IFERROR(VLOOKUP(A16,'Stock Loeke'!A:G,7,),),)+IF(B16="CH",IFERROR(VLOOKUP(A16,'Stock Chef'!A:J,10,),0),0) -> 0 | L16: 576 | M16: =+K16+L16 -> 576 | N16: 24 | O16: 0 | P16: 24 | Q16: 24
A17: 606E | B17: LK | C17: Becky 1 | D17: Pinza 30 cm Ac Inox c/ Silic | E17: 0.56 | F17: =+E17*IF(ISNUMBER(H17),H17,G17) -> 0 | G17: =IF((+I17-M17)<0,0,+I17-M17) -> 288 | H17: 0 | I17: =+$I$3*N17 -> 2880 | J17: =IFERROR(+M17/N17,"") -> 7.2 | K17: =+IF(B17<>"CH",IFERROR(VLOOKUP(A17,'Stock Loeke'!A:G,7,),),)+IF(B17="CH",IFERROR(VLOOKUP(A17,'Stock Chef'!A:J,10,),0),0) -> 1032 | L17: 1560 | M17: =+K17+L17 -> 2592 | N17: 360 | O17: 300 | P17: 228 | Q17: 456 | R17: =IFERROR(+VLOOKUP(A17,Quiebres!A:Q,17,0),"") | S17: 606E
A18: 607E | B18: LK | C18: Becky 1 | D18: Pinza Hielo 15 cm | E18: 0.26 | F18: =+E18*IF(ISNUMBER(H18),H18,G18) -> 0 | G18: =IF((+I18-M18)<0,0,+I18-M18) -> 540 | H18: 0 | I18: =+$I$3*N18 -> 7200 | J18: =IFERROR(+M18/N18,"") -> 7.4 | K18: =+IF(B18<>"CH",IFERROR(VLOOKUP(A18,'Stock Loeke'!A:G,7,),),)+IF(B18="CH",IFERROR(VLOOKUP(A18,'Stock Chef'!A:J,10,),0),0) -> 5220 | L18: 1440 | M18: =+K18+L18 -> 6660 | N18: 900 | O18: 144 | P18: 288 | Q18: 816 | R18: =IFERROR(+VLOOKUP(A18,Quiebres!A:Q,17,0),"") | S18: 607E
A19: 941E | B19: LK | C19: Becky 2 | D19: Espatula Lisa Ac. Inox | E19: 0.66 | F19: =+E19*IF(ISNUMBER(H19),H19,G19) -> 0 | G19: =IF((+I19-M19)<0,0,+I19-M19) -> 128 | H19: 0 | I19: =+$I$3*N19 -> 3200 | J19: =IFERROR(+M19/N19,"") -> 7.68 | K19: =+IF(B19<>"CH",IFERROR(VLOOKUP(A19,'Stock Loeke'!A:G,7,),),)+IF(B19="CH",IFERROR(VLOOKUP(A19,'Stock Chef'!A:J,10,),0),0) -> 624 | L19: 2448 | M19: =+K19+L19 -> 3072 | N19: 400 | O19: 0 | P19: 264 | Q19: 216 | R19: =IFERROR(+VLOOKUP(A19,Quiebres!A:Q,17,0),"") | S19: 941E
A20: 601E | B20: LK | C20: Becky | D20: Pinza 30cm Ac. Puntera Silic | E20: 0.735 | F20: =+E20*IF(ISNUMBER(H20),H20,G20) -> 0 | G20: =IF((+I20-M20)<0,0,+I20-M20) -> 3448 | H20: 0 | I20: =+$I$3*N20 -> 5776 | J20: =IFERROR(+M20/N20,"") -> 3.2243767 | K20: =+IF(B20<>"CH",IFERROR(VLOOKUP(A20,'Stock Loeke'!A:G,7,),),)+IF(B20="CH",IFERROR(VLOOKUP(A20,'Stock Chef'!A:J,10,),0),0) -> 2328 | L20: 0 | M20: =+K20+L20 -> 2328 | N20: 722 | O20: 288 | P20: 228 | Q20: 252 | R20: =IFERROR(+VLOOKUP(A20,Quiebres!A:Q,17,0),"") | S20: 601E
A21: 956E | B21: LK | C21: Becky 1 | D21: Cuchara Calada Silic Mgo Bambú | E21: 0.49 | F21: =+E21*IF(ISNUMBER(H21),H21,G21) -> 0 | G21: =IF((+I21-M21)<0,0,+I21-M21) -> 60 | H21: 0 | I21: =+$I$3*N21 -> 2400 | J21: =IFERROR(+M21/N21,"") -> 7.8 | K21: =+IF(B21<>"CH",IFERROR(VLOOKUP(A21,'Stock Loeke'!A:G,7,),),)+IF(B21="CH",IFERROR(VLOOKUP(A21,'Stock Chef'!A:J,10,),0),0) -> 612 | L21: 1728 | M21: =+K21+L21 -> 2340 | N21: 300 | O21: 12 | P21: 312 | Q21: 60 | R21: =IFERROR(+VLOOKUP(A21,Quiebres!A:Q,17,0),"") | S21: 956E
A22: 946E | B22: LK | C22: Becky 2 | D22: Cuchara Calada Ac. Inox | E22: 0.66 | F22: =+E22*IF(ISNUMBER(H22),H22,G22) -> 0 | G22: =IF((+I22-M22)<0,0,+I22-M22) -> 40 | H22: 0 | I22: =+$I$3*N22 -> 3040 | J22: =IFERROR(+M22/N22,"") -> 7.8947368 | K22: =+IF(B22<>"CH",IFERROR(VLOOKUP(A22,'Stock Loeke'!A:G,7,),),)+IF(B22="CH",IFERROR(VLOOKUP(A22,'Stock Chef'!A:J,10,),0),0) -> 696 | L22: 2304 | M22: =+K22+L22 -> 3000 | N22: 380 | O22: 0 | P22: 252 | Q22: 84 | R22: =IFERROR(+VLOOKUP(A22,Quiebres!A:Q,17,0),"") | S22: 946E
A23: 980E | B23: LK | C23: Becky | D23: Tenedor Ensalada Linea Premium | E23: 0.96 | F23: =+E23*IF(ISNUMBER(H23),H23,G23) -> 0 | G23: =IF((+I23-M23)<0,0,+I23-M23) -> 0 | H23: 0 | I23: =+$I$3*N23 -> 672 | J23: =IFERROR(+M23/N23,"") -> 8 | K23: =+IF(B23<>"CH",IFERROR(VLOOKUP(A23,'Stock Loeke'!A:G,7,),),)+IF(B23="CH",IFERROR(VLOOKUP(A23,'Stock Chef'!A:J,10,),0),0) -> 672 | L23: 0 | M23: =+K23+L23 -> 672 | N23: 84 | O23: 12 | P23: 60 | Q23: 84 | R23: =IFERROR(+VLOOKUP(A23,Quiebres!A:Q,17,0),"") | S23: 980E
A24: 953E | B24: LK | C24: Becky 1 | D24: Cucharon Silicona Mgo Bambú | E24: 0.49 | F24: =+E24*IF(ISNUMBER(H24),H24,G24) -> 0 | G24: =IF((+I24-M24)<0,0,+I24-M24) -> 0 | H24: 0 | I24: =+$I$3*N24 -> 3360 | J24: =IFERROR(+M24/N24,"") -> 8.2857143 | K24: =+IF(B24<>"CH",IFERROR(VLOOKUP(A24,'Stock Loeke'!A:G,7,),),)+IF(B24="CH",IFERROR(VLOOKUP(A24,'Stock Chef'!A:J,10,),0),0) -> 312 | L24: 3168 | M24: =+K24+L24 -> 3480 | N24: 420 | O24: 456 | P24: 432 | Q24: 156 | R24: =IFERROR(+VLOOKUP(A24,Quiebres!A:Q,17,0),"") | S24: 953E
A25: 945E | B25: LK | C25: Becky | D25: Espatula Calada Ac. Inox | E25: 0.66 | F25: =+E25*IF(ISNUMBER(H25),H25,G25) -> 0 | G25: =IF((+I25-M25)<0,0,+I25-M25) -> 0 | H25: 0 | I25: =+$I$3*N25 -> 3040 | J25: =IFERROR(+M25/N25,"") -> 8.7473684 | K25: =+IF(B25<>"CH",IFERROR(VLOOKUP(A25,'Stock Loeke'!A:G,7,),),)+IF(B25="CH",IFERROR(VLOOKUP(A25,'Stock Chef'!A:J,10,),0),0) -> -276 | L25: 3600 | M25: =+K25+L25 -> 3324 | N25: 380 | O25: 12 | P25: 276 | Q25: 252 | R25: =IFERROR(+VLOOKUP(A25,Quiebres!A:Q,17,0),"") | S25: 945E
A26: 943E | B26: LK | C26: Becky 2 | D26: Cucharon Ac. Inox | E26: 0.66 | F26: =+E26*IF(ISNUMBER(H26),H26,G26) -> 0 | G26: =IF((+I26-M26)<0,0,+I26-M26) -> 2272 | H26: 0 | I26: =+$I$3*N26 -> 4000 | J26: =IFERROR(+M26/N26,"") -> 3.456 | K26: =+IF(B26<>"CH",IFERROR(VLOOKUP(A26,'Stock Loeke'!A:G,7,),),)+IF(B26="CH",IFERROR(VLOOKUP(A26,'Stock Chef'!A:J,10,),0),0) -> -288 | L26: 2016 | M26: =+K26+L26 -> 1728 | N26: 500 | O26: 0 | P26: 264 | Q26: 384 | R26: =IFERROR(+VLOOKUP(A26,Quiebres!A:Q,17,0),"") | S26: 943E
A27: 942E | B27: LK | C27: Becky 2 | D27: Cuchara Ac. Inox | E27: 0.66 | F27: =+E27*IF(ISNUMBER(H27),H27,G27) -> 0 | G27: =IF((+I27-M27)<0,0,+I27-M27) -> 1348 | H27: 0 | I27: =+$I$3*N27 -> 4000 | J27: =IFERROR(+M27/N27,"") -> 5.304 | K27: =+IF(B27<>"CH",IFERROR(VLOOKUP(A27,'Stock Loeke'!A:G,7,),),)+IF(B27="CH",IFERROR(VLOOKUP(A27,'Stock Chef'!A:J,10,),0),0) -> -228 | L27: 2880 | M27: =+K27+L27 -> 2652 | N27: 500 | O27: 12 | P27: 288 | Q27: 276 | R27: =IFERROR(+VLOOKUP(A27,Quiebres!A:Q,17,0),"") | S27: 942E
A28: 971E | B28: LK | C28: Becky 2 | D28: Espatula Silicona Mgo Plastico | E28: 0.39 | F28: =+E28*IF(ISNUMBER(H28),H28,G28) -> 0 | G28: =IF((+I28-M28)<0,0,+I28-M28) -> 0 | H28: 0 | I28: =+$I$3*N28 -> 2880 | J28: =IFERROR(+M28/N28,"") -> 8.5666667 | K28: =+IF(B28<>"CH",IFERROR(VLOOKUP(A28,'Stock Loeke'!A:G,7,),),)+IF(B28="CH",IFERROR(VLOOKUP(A28,'Stock Chef'!A:J,10,),0),0) -> 348 | L28: 2736 | M28: =+K28+L28 -> 3084 | N28: 360 | O28: 936 | P28: 348 | Q28: 204 | R28: =IFERROR(+VLOOKUP(A28,Quiebres!A:Q,17,0),"") | S28: 971E
... A42: 933E | B42: LK | C42: Becky 1 | D42: Cucharon Nylon Mgo Madera | E42: 0.53 | F42: =+E42*IF(ISNUMBER(H42),H42,G42) -> 0 | G42: =IF((+I42-M42)<0,0,+I42-M42) -> 0 | H42: 0 | I42: =+$I$3*N42 -> 1824 | J42: =IFERROR(+M42/N42,"") -> 11 | K42: =+IF(B42<>"CH",IFERROR(VLOOKUP(A42,'Stock Loeke'!A:G,7,),),)+IF(B42="CH",IFERROR(VLOOKUP(A42,'Stock Chef'!A:J,10,),0),0) -> 1788 | L42: 720 | M42: =+K42+L42 -> 2508 | N42: 228 | O42: 228 | P42: 180 | Q42: 84 | R42: =IFERROR(+VLOOKUP(A42,Quiebres!A:Q,17,0),"") | S42: 933E
A43: 404E | B43: LK | C43: Becky 1/2 | D43: Afila Chuchillos Premiun | E43: 5.2 | F43: =+E43*IF(ISNUMBER(H43),H43,G43) -> 0 | G43: =IF((+I43-M43)<0,0,+I43-M43) -> 0 | H43: 0 | I43: =+$I$3*N43 -> 2272 | J43: =IFERROR(+M43/N43,"") -> 11.535211 | K43: =+IF(B43<>"CH",IFERROR(VLOOKUP(A43,'Stock Loeke'!A:G,7,),),)+IF(B43="CH",IFERROR(VLOOKUP(A43,'Stock Chef'!A:J,10,),0),0) -> 1452 | L43: =928+896 -> 1824 | M43: =+K43+L43 -> 3276 | N43: 284 | O43: 184 | P43: 200 | Q43: 284 | R43: =IFERROR(+VLOOKUP(A43,Quiebres!A:Q,17,0),"") | S43: 404E
A44: 969E | B44: LK | C44: Becky 2 | D44: Batidor Silicona Mgo. Plastico | E44: 0.53 | F44: =+E44*IF(ISNUMBER(H44),H44,G44) -> 0 | G44: =IF((+I44-M44)<0,0,+I44-M44) -> 0 | H44: 0 | I44: =+$I$3*N44 -> 1152 | J44: =IFERROR(+M44/N44,"") -> 11.416667 | K44: =+IF(B44<>"CH",IFERROR(VLOOKUP(A44,'Stock Loeke'!A:G,7,),),)+IF(B44="CH",IFERROR(VLOOKUP(A44,'Stock Chef'!A:J,10,),0),0) -> 636 | L44: 1008 | M44: =+K44+L44 -> 1644 | N44: 144 | O44: 900 | P44: 144 | Q44: 132 | R44: =IFERROR(+VLOOKUP(A44,Quiebres!A:Q,17,0),"") | S44: 969E
A45: 984E | B45: LK | C45: Becky | D45: Cuchara Fideos Linea Premium | E45: 1.35 | F45: =+E45*IF(ISNUMBER(H45),H45,G45) -> 0 | G45: =IF((+I45-M45)<0,0,+I45-M45) -> 0 | H45: 0 | I45: =+$I$3*N45 -> 480 | J45: =IFERROR(+M45/N45,"") -> 12 | K45: =+IF(B45<>"CH",IFERROR(VLOOKUP(A45,'Stock Loeke'!A:G,7,),),)+IF(B45="CH",IFERROR(VLOOKUP(A45,'Stock Chef'!A:J,10,),0),0) -> 720 | L45: 0 | M45: =+K45+L45 -> 720 | N45: 60 | O45: 12 | P45: 60 | Q45: 48 | R45: =IFERROR(+VLOOKUP(A45,Quiebres!A:Q,17,0),"") | S45: 984E
A46: 982E | B46: LK | C46: Becky 2 | D46: Cuchara Linea Premium | E46: 0.98 | F46: =+E46*IF(ISNUMBER(H46),H46,G46) -> 0 | G46: =IF((+I46-M46)<0,0,+I46-M46) -> 0 | H46: 0 | I46: =+$I$3*N46 -> 1920 | J46: =IFERROR(+M46/N46,"") -> 12.8 | K46: =+IF(B46<>"CH",IFERROR(VLOOKUP(A46,'Stock Loeke'!A:G,7,),),)+IF(B46="CH",IFERROR(VLOOKUP(A46,'Stock Chef'!A:J,10,),0),0) -> 624 | L46: 2448 | M46: =+K46+L46 -> 3072 | N46: 240 | O46: 24 | P46: 228 | Q46: 252 | R46: =IFERROR(+VLOOKUP(A46,Quiebres!A:Q,17,0),"") | S46: 982E
A47: 954E | B47: LK | C47: Becky 1 | D47: Cuchara Fideos Silic Mgo Bambú | E47: 0.49 | F47: =+E47*IF(ISNUMBER(H47),H47,G47) -> 0 | G47: =IF((+I47-M47)<0,0,+I47-M47) -> 0 | H47: 0 | I47: =+$I$3*N47 -> 1600 | J47: =IFERROR(+M47/N47,"") -> 13.74 | K47: =+IF(B47<>"CH",IFERROR(VLOOKUP(A47,'Stock Loeke'!A:G,7,),),)+IF(B47="CH",IFERROR(VLOOKUP(A47,'Stock Chef'!A:J,10,),0),0) -> 732 | L47: 2016 | M47: =+K47+L47 -> 2748 | N47: 200 | O47: 0 | P47: 204 | Q47: 48 | R47: =IFERROR(+VLOOKUP(A47,Quiebres!A:Q,17,0),"") | S47: 954E
A48: 981E | B48: LK | C48: Becky 2 | D48: Espátula Lisa Linea Premium | E48: 1.3 | F48: =+E48*IF(ISNUMBER(H48),H48,G48) -> 0 | G48: =IF((+I48-M48)<0,0,+I48-M48) -> 0 | H48: 0 | I48: =+$I$3*N48 -> 576 | J48: =IFERROR(+M48/N48,"") -> 23.166667 | K48: =+IF(B48<>"CH",IFERROR(VLOOKUP(A48,'Stock Loeke'!A:G,7,),),)+IF(B48="CH",IFERROR(VLOOKUP(A48,'Stock Chef'!A:J,10,),0),0) -> 660 | L48: 1008 | M48: =+K48+L48 -> 1668 | N48: 72 | O48: 24 | P48: 72 | Q48: 84 | R48: =IFERROR(+VLOOKUP(A48,Quiebres!A:Q,17,0),"") | S48: 981E
A49: 983E | B49: LK | C49: Becky 2 | D49: Cucharón Linea Premium | E49: 1.98 | F49: =+E49*IF(ISNUMBER(H49),H49,G49) -> 0 | G49: =IF((+I49-M49)<0,0,+I49-M49) -> 0 | H49: 0 | I49: =+$I$3*N49 -> 560 | J49: =IFERROR(+M49/N49,"") -> 26.914286 | K49: =+IF(B49<>"CH",IFERROR(VLOOKUP(A49,'Stock Loeke'!A:G,7,),),)+IF(B49="CH",IFERROR(VLOOKUP(A49,'Stock Chef'!A:J,10,),0),0) -> 876 | L49: 1008 | M49: =+K49+L49 -> 1884 | N49: 70 | O49: 12 | P49: 36 | Q49: 108 | R49: =IFERROR(+VLOOKUP(A49,Quiebres!A:Q,17,0),"") | S49: 983E
A50: 938E | B50: LK | C50: Becky 1 | D50: Espumadera Nylon Mgo Madera | E50: 0.5 | F50: =+E50*IF(ISNUMBER(H50),H50,G50) -> 0 | G50: =IF((+I50-M50)<0,0,+I50-M50) -> 0 | H50: 0 | I50: =+$I$3*N50 -> 0 | J50: =IFERROR(+M50/N50,"") | K50: =+IF(B50<>"CH",IFERROR(VLOOKUP(A50,'Stock Loeke'!A:G,7,),),)+IF(B50="CH",IFERROR(VLOOKUP(A50,'Stock Chef'!A:J,10,),0),0) -> 0 | L50: 2880 | M50: =+K50+L50 -> 2880 | N50: 0 | O50: 0 | P50: 0 | Q50: 0 | R50: =IFERROR(+VLOOKUP(A50,Quiebres!A:Q,17,0),"") | S50: NO
A51: 602E | B51: LK | C51: Becky 2 | D51: Pinza 25cm Ac. Puntera Silic | E51: 0.65 | F51: =+E51*IF(ISNUMBER(H51),H51,G51) -> 0 | G51: =IF((+I51-M51)<0,0,+I51-M51) -> 0 | H51: 0 | I51: =+$I$3*N51 -> 0 | J51: =IFERROR(+M51/N51,"") | K51: =+IF(B51<>"CH",IFERROR(VLOOKUP(A51,'Stock Loeke'!A:G,7,),),)+IF(B51="CH",IFERROR(VLOOKUP(A51,'Stock Chef'!A:J,10,),0),0) -> 0 | L51: 1080 | M51: =+K51+L51 -> 1080 | N51: 0 | O51: 0 | P51: 0 | Q51: 0 | R51: =IFERROR(+VLOOKUP(A51,Quiebres!A:Q,17,0),"") | S51: NO
A52: 930E | B52: LK | C52: Becky | D52: Pisa Papas Nylon Mgo Madera | E52: 0 | F52: =+E52*IF(ISNUMBER(H52),H52,G52) -> 0 | G52: =IF((+I52-M52)<0,0,+I52-M52) -> 0 | H52: 0 | I52: =+$I$3*N52 -> 0 | J52: =IFERROR(+M52/N52,"") | K52: =+IF(B52<>"CH",IFERROR(VLOOKUP(A52,'Stock Loeke'!A:G,7,),),)+IF(B52="CH",IFERROR(VLOOKUP(A52,'Stock Chef'!A:J,10,),0),0) -> 0 | L52: 0 | M52: =+K52+L52 -> 0 | N52: 0 | O52: 0 | P52: 0 | Q52: 0 | R52: =IFERROR(+VLOOKUP(A52,Quiebres!A:Q,17,0),"") | S52: NO
A53: 939E | B53: LK | C53: Becky | D53: Espatula Nylon Mgo Madera | E53: 0 | F53: =+E53*IF(ISNUMBER(H53),H53,G53) -> 0 | G53: =IF((+I53-M53)<0,0,+I53-M53) -> 0 | H53: 0 | I53: =+$I$3*N53 -> 0 | J53: =IFERROR(+M53/N53,"") | K53: =+IF(B53<>"CH",IFERROR(VLOOKUP(A53,'Stock Loeke'!A:G,7,),),)+IF(B53="CH",IFERROR(VLOOKUP(A53,'Stock Chef'!A:J,10,),0),0) -> 0 | L53: 0 | M53: =+K53+L53 -> 0 | N53: 0 | O53: 0 | P53: 0 | Q53: 0 | R53: =IFERROR(+VLOOKUP(A53,Quiebres!A:Q,17,0),"") | S53: NO
...

Sheet Stock Loeke
A1: Cód.Artículo | B1: Descripción | C1: Med. | D1: Stock | E1: Pedido | F1: Pedido Kit/Cbo | G1: Stock | H1: Compras | I1: Cpras Kit/Cbo | J1: Stock
A2: 0007 | B2: espiral para loeke | C2: unidad | D2: 15500 | E2: 0 | F2: 0 | G2: 15500 | H2: 0 | I2: 0 | J2: 15500
A3: 025 | B3: Ø 7 Env. | C3: unidad | D3: 0 | E3: 0 | F3: 0 | G3: 0 | H3: 7452 | I3: 0 | J3: 7452
A4: 026 | B4: Ø 8 Env. | C4: unidad | D4: 10944 | E4: 4968 | F4: 0 | G4: 5976 | H4: 16848 | I4: 0 | J4: 22824
A5: 027 | B5: Ø - COLADOR N°10 | C5: unidad | D5: 4440 | E5: 5232 | F5: 0 | G5: -792 | H5: 50832 | I5: 0 | J5: 50040
A6: 028 | B6: Ø 13 Env. | C6: unidad | D6: 0 | E6: 0 | F6: 0 | G6: 0 | H6: 936 | I6: 0 | J6: 936
A7: 029 | B7: Ø 16 Env. | C7: unidad | D7: 96 | E7: 0 | F7: 0 | G7: 96 | H7: 1704 | I7: 0 | J7: 1800
A8: 030 | B8: Ø 20 Env. | C8: unidad | D8: 48 | E8: 0 | F8: 0 | G8: 48 | H8: 2232 | I8: 0 | J8: 2280
A9: 031 | B9: Filtros de Café | C9: unidad | D9: 9312 | E9: 11808 | F9: 0 | G9: -2496 | H9: 34128 | I9: 0 | J9: 31632
A10: 034 | B10: Filtro de Café Gastronomico | C10: unidad | D10: 1032 | E10: 696 | F10: 0 | G10: 336 | H10: 0 | I10: 0 | J10: 336
A11: 035E | B11: Cernidor Harina Ac. Inox. | C11: unidad | D11: 660 | E11: 48 | F11: 0 | G11: 612 | H11: 0 | I11: 0 | J11: 612
A12: 056E | B12: Destapador Full Black | C12: unidad | D12: 4644 | E12: 24 | F12: 0 | G12: 4620 | H12: 0 | I12: 0 | J12: 4620
A13: 057 | B13: Destapa Corona * 1 Env. | C13: unidad | D13: 972 | E13: 96 | F13: 0 | G13: 876 | H13: 0 | I13: 0 | J13: 876
... A281: D208 | B281: Cucharita 13cm Azucarera Mader | C281: unidad | D281: 0 | E281: 0 | F281: 0 | G281: 0 | H281: 384 | I281: 0 | J281: 384
A282: Impreso por: | B282: MARIANELA | C282: 46205 | D282: 36494.693 | E282: Hoja Nro: | F282: 1 | G282: de | H282: 1

Sheet Stock Chef
A1: Cód.Artículo | B1: Descripción | D1: Med. | F1: Stock | G1: Pedido | H1: Pedido Kit/Cbo | J1: Stock | K1: Compras | L1: Cpras Kit/Cbo | M1: Stock
D2: 1 | G2: División Unica
A3: 031L | B3: FILTRO DE CAFE | D3: unidad | F3: 0 | G3: 96 | H3: 0 | J3: -96 | K3: 0 | L3: 0 | M3: -96
A4: 034L | B4: FILTRO DE CAFE GASTRONOMICO | D4: unidad | F4: 0 | G4: 96 | H4: 0 | J4: -96 | K4: 0 | L4: 0 | M4: -96
A5: 035E | B5: Cernidor de Harina Ac. Inox | D5: unidad | F5: 72 | G5: 0 | H5: 0 | J5: 72 | K5: 0 | L5: 0 | M5: 72
A6: 035EL | B6: Cernidor Harina Ac. Inox. | D6: unidad | F6: 0 | G6: 24 | H6: 0 | J6: -24 | K6: 0 | L6: 0 | M6: -24
A7: 043 | B7: TRES EN UNO | D7: unidad | F7: 816 | G7: 24 | H7: 0 | J7: 792 | K7: 456 | L7: 0 | M7: 1248
A8: 052 | B8: LAVAVAJILLA C/MGO.ARTE | D8: unidad | F8: 586 | G8: 0 | H8: 0 | J8: 586 | K8: 0 | L8: 0 | M8: 586
A9: 053 | B9: PINZA DE FIAMBRE x 12 | D9: unidad | F9: 48 | G9: 12 | H9: 0 | J9: 36 | K9: 0 | L9: 0 | M9: 36
A10: 054 | B10: PINZA DE ENSALADAS x 12 | D10: unidad | F10: 1272 | G10: 36 | H10: 0 | J10: 1236 | K10: 0 | L10: 0 | M10: 1236
A11: 055 | B11: PINZA DE FIDEOS x 12 | D11: unidad | F11: 252 | G11: 132 | H11: 0 | J11: 120 | K11: 24 | L11: 0 | M11: 144
A12: 056 | B12: DESCAROZADOR DE ACEITUNAS | D12: unidad | F12: 0 | G12: 0 | H12: 0 | J12: 0 | K12: 120 | L12: 0 | M12: 120
A13: 058L | B13: CIERRA BOLSA X 2 | D13: unidad | F13: 0 | G13: 24 | H13: 0 | J13: -24 | K13: 0 | L13: 0 | M13: -24
A14: 059L | B14: CUCHILLITO DE UNTAR PLAST X 2 | D14: unidad | F14: 0 | G14: 24 | H14: 0 | J14: -24 | K14: 0 | L14: 0 | M14: -24
... A240: 971EL | B240: Espatula Silicona Mgo Plastico | D240: unidad | F240: 948 | G240: 0 | H240: 0 | J240: 948 | K240: 0 | L240: 0 | M240: 948
A241: Impreso por: | B241: MARIANELA | C241: 46205 | D241: 36494.694 | K241: Hoja Nro: | L241: 1 | M241: de | N241: 1
